Workbook

Sheet KWITANSI FULL 
A1: AL- QOYYUM ROYAL CLINIC
A2: Jl. Buana Indah No.61 Cihideung-Sadang-Purwakarta
A3: No. SIPD : 446/SIPD-1785/DPMPTSP/2022
A4: Telp : (0264)8464554 / 0813.1314.8633 (WA) | I4: No. SIPD : 446/SIPD-1785/DPMPTSP/2022
A6: NO : 367/1026
A7: Diterima dari | C7: : Ny. | D7: Yayuk Novita Dewi | G7: =TODAY() -> 46301
A8: Nama Pasien | C8: : Ny. | D8: =D7 -> Yayuk Novita Dewi
A9: Nama Dokter | C9: : dr. | D9: Maulia Mardini, SpOG, MARS,
A10: Untuk Pembayaran
A11: Jasa | B11: Konsultasi Dokter | G11: =VLOOKUP(B11,HARGA!$B$3:$D$181,3,FALSE) -> 120000
B12: USG 2D | G12: =VLOOKUP(B12,HARGA!$B$3:$D$181,3,FALSE) -> 80000
B13: Irigasi Vagina | G13: =VLOOKUP(B13,HARGA!$B$3:$D$181,3,FALSE) -> 275000
A14: Obat | B14: Kalnex | E14: 10 | F14: pcs | G14: =VLOOKUP(B14,HARGA!$B$3:$D$181,3,FALSE)*E14 -> 75000 | J14: `
B15: Zoltin | E15: 5 | F15: pcs | G15: =VLOOKUP(B15,HARGA!$B$3:$D$181,3,FALSE)*E15 -> 125000
B16: Cefixime | E16: 6 | F16: pcs | G16: =VLOOKUP(B16,HARGA!$B$3:$D$181,3,FALSE)*E16 -> 42000
B17: Kasa | E17: 1 | F17: pcs | G17: =VLOOKUP(B17,HARGA!$B$3:$D$181,3,FALSE)*E17 -> 10000
B18: Underpads | E18: 1 | F18: pcs | G18: =VLOOKUP(B18,HARGA!$B$3:$D$181,3,FALSE)*E18 -> 10000
B19: Pembalut | E19: 1 | F19: pcs | G19: 2000
A21: Total Pembayaran | G21: =SUM(G11:G20) -> 739000
A23: Cara Pembayaran | C23: :
A24: Terbilang | C24: : | D24: =PROPER([1]!terbilang(G21))&"Rupiah" -> Tujuhratus Tigapuluh Sembilan Ribu Rupiah
G26: Diterima oleh:
G29: Nunung Nurjanah
A35: Jl. Buana Indah No.61 Cihideung-Sadang-Purwakarta
A36: Telp : (0264)8464554 / 0813.1314.8633 (WA)
A37: BUKTI PEMBAYARAN
A38: =A6 -> NO : 367/1026
A40: Diterima dari | C40: : Ny. | D40: =D7 -> Yayuk Novita Dewi | G40: =TODAY() -> 46301
A41: Nama Pasien | C41: : Ny. | D41: =D40 -> Yayuk Novita Dewi
A42: Nama Dokter | C42: : dr. | D42: Maulia Mardini, SpOG, MARS,
A43: Untuk Pembayaran
A44: Jasa | B44: Konsultasi Dokter | G44: =VLOOKUP(B44,HARGA!$B$3:$D$181,3,FALSE) -> 120000
B45: USG 2D | G45: =VLOOKUP(B45,HARGA!$B$3:$D$181,3,FALSE) -> 80000
B46: Insersi IUD | G46: =VLOOKUP(B46,HARGA!$B$3:$D$181,3,FALSE) -> 450000
A47: Obat | B47: Cefixime | E47: 6 | F47: pcs | G47: =VLOOKUP(B47,HARGA!$B$3:$D$181,3,FALSE)*E47 -> 42000
B48: Kasa | E48: 1 | F48: pcs | G48: =VLOOKUP(B48,HARGA!$B$3:$D$181,3,FALSE)*E48 -> 10000
B49: Nova T IUD | E49: 1 | F49: pcs | G49: =VLOOKUP(B49,HARGA!$B$3:$D$181,3,FALSE)*E49 -> 650000
A51: Total Pembayaran | G51: =SUM(G44:G50) -> 1352000
A52: Cara Pembayaran | C52: :
A53: Terbilang | C53: : | D53: =PROPER([1]!terbilang(G51))&"Rupiah" -> Satu Juta Tigaratus Limapuluh Dua Ribu Rupiah
...

Sheet KWITANSI jasa
A1: AL-QOYYUM ROYAL CLINIC
A2: Jl. Buana Indah No.61 Cihideung-Sadang-Purwakarta
A3: Telp : (0264)8464554 / 0813.1314.8633 (WA)
A4: BUKTI PEMBAYARAN
A5: ='KWITANSI FULL '!A6:G6 -> NO : 367/1026
A7: Diterima dari | C7: : Ny. | D7: ='KWITANSI FULL '!D7 -> Yayuk Novita Dewi | G7: =TODAY() -> 46301
A8: Nama Pasien | C8: : Ny. | D8: =D7 -> Yayuk Novita Dewi
A9: Nama Dokter | C9: : dr. | D9: Maulia Mardini, SpOG, MARS,
A10: Untuk Pembayaran
A11: Jasa | B11: Konsultasi Dokter | G11: =VLOOKUP(B11,HARGA!$B$3:$D$181,3,FALSE) -> 120000
B12: USG 2D | G12: =VLOOKUP(B12,HARGA!$B$3:$D$181,3,FALSE) -> 80000
A14: Total Pembayaran | G14: =SUM(G11:G12) -> 200000
A17: Cara Pembayaran | C17: :
A18: Terbilang | C18: : | D18: =PROPER([1]!terbilang(G14))&"Rupiah" -> Duaratus Ribu Rupiah
G20: Diterima oleh:
G23: Nunung Nurjanah
A29: AL-QOYYUM ROYAL CLINIC
A30: Jl. Buana Indah No.61 Cihideung-Sadang-Purwakarta
A31: Telp : (0264)8464554 / 0813.1314.8633 (WA)
A32: BUKTI PEMBAYARAN
A33: =A5 -> NO : 367/1026
A35: Diterima dari | C35: : Ny. | D35: Sinta Yunita | G35: =TODAY() -> 46301
A36: Nama Pasien | C36: =C35 -> : Ny. | D36: =D35 -> Sinta Yunita
A37: Nama Dokter | C37: : dr. Maulia Mardini, SpOG, MARS | D37: maulia Mardini, SpOG, MARS,
A38: Untuk Pembayaran
A39: Jasa : | B39: Konsultasi Dokter | G39: =VLOOKUP(B39,HARGA!$B$3:$C$192,2,FALSE) -> 120000
B40: USG 2D | G40: =VLOOKUP(B40,HARGA!$B$3:$C$192,2,FALSE) -> 80000
B41: Periksa Dalam | F41: 4x | G41: 140000
B42: Alkes | G42: 160000
A44: Total Pembayaran | G44: =SUM(G39:G42) -> 500000
A47: Cara Pembayaran | C47: : | D47: Cash
A48: Terbilang | C48: : | D48: Lima Ratus Ribu Rupiah
G50: Diterima oleh:
G53: Nunung Nurjanah

Sheet KWITANSI obat
A1: AL-QOYYUM ROYAL CLINIC
A2: Jl. Buana Indah No.61 Cihideung-Sadang-Purwakarta
A3: Telp : (0264)8464554 / 0813.1314.8633 (WA)
A4: BUKTI PEMBAYARAN
A5: ='KWITANSI FULL '!A6:G6 -> NO : 367/1026
A7: Diterima dari | C7: : Ny. | D7: ='KWITANSI FULL '!D7 -> Yayuk Novita Dewi | G7: =TODAY() -> 46301
A8: Nama Pasien | C8: : Ny. | D8: =D7 -> Yayuk Novita Dewi
A9: Nama Dokter | C9: : dr. | D9: Maulia Mardini, SpOG, MARS,
A10: Untuk Pembayaran
A12: Obat | B12: Microgest 200 mg | E12: 2 | F12: pcs | G12: =VLOOKUP(B12,HARGA!$B$3:$D$181,3,FALSE)*E12 -> 74000
B13: Sanmol | E13: 8 | F13: pcs | G13: =VLOOKUP(B13,HARGA!$B$3:$D$181,3,FALSE)*E13 -> 8000
A15: Total Pembayaran | G15: =SUM(G12:G14) -> 82000
A17: Cara Pembayaran | C17: :
A18: Terbilang | C18: : | D18: =PROPER([1]!terbilang(G15))&"Rupiah" -> Delapanpuluh Dua Ribu Rupiah
G20: Diterima oleh:
G23: Nunung Nurjanah
A27: =A1 -> AL-QOYYUM ROYAL CLINIC
A28: Jl. Buana Indah No.61 Cihideung-Sadang-Purwakarta
A29: Telp : (0264)8464554 / 0813.1314.8633 (WA)
A30: BUKTI PEMBAYARAN
A31: =A5 -> NO : 367/1026
A33: Diterima dari | C33: : Ny. | D33: Widya Ningsih Sudarman | G33: =TODAY() -> 46301
A34: Nama Pasien | C34: : Ny. | D34: =D33 -> Widya Ningsih Sudarman
A35: Nama Dokter | C35: : dr. | D35: Maulia Mardini, SpOG, MARS,
A36: Untuk Pembayaran
A37: Jasa : | B37: Konsultasi Dokter | G37: =VLOOKUP(B37,HARGA!$B$3:$D$181,3,FALSE) -> 120000
B38: USG 2D | G38: =VLOOKUP(B38,HARGA!$B$3:$D$181,3,FALSE) -> 80000
B39: Insersi IUD | G39: =VLOOKUP(B39,HARGA!$B$3:$D$181,3,FALSE) -> 450000
A40: Obat : | B40: Cefixime | E40: 6 | F40: Pcs | G40: =VLOOKUP(B40,HARGA!$B$3:$D$181,3,FALSE)*E40 -> 42000
B41: Kasa | E41: 1 | F41: Pcs | G41: =VLOOKUP(B41,HARGA!$B$3:$D$181,3,FALSE)*E41 -> 10000
B42: Nova T IUD | E42: 1 | F42: Pcs | G42: =VLOOKUP(B42,HARGA!$B$3:$D$181,3,FALSE)*E42 -> 650000
B43: Underpads | E43: 1 | F43: Pcs | G43: =VLOOKUP(B43,HARGA!$B$3:$D$181,3,FALSE)*E43 -> 10000
A45: Total Pembayaran | G45: =SUM(G37:G44) -> 1362000
A47: Cara Pembayaran | C47: : | D47: Cash
A48: Terbilang | C48: : | D48: =PROPER([1]!terbilang(G45))&"Rupiah" -> Satu Juta Tigaratus Enampuluh Dua Ribu Rupiah
G50: Diterima oleh:
G53: Nunung Nurjanah

Sheet KWITANSI obat (2)
A1: AL-QOYYUM ROYAL CLINIC
A2: Jl. Buana Indah No.61 Cihideung-Sadang-Purwakarta
A3: Telp : (0264)8464554 / 0813.1314.8633 (WA)
A4: BUKTI PEMBAYARAN
A5: ='KWITANSI FULL '!A6:G6 -> NO : 367/1026
A7: Diterima dari | C7: : Ny. | D7: ='KWITANSI FULL '!D7 -> Yayuk Novita Dewi | G7: =TODAY() -> 46301
A8: Nama Pasien | C8: : Ny. | D8: =D7 -> Yayuk Novita Dewi
A9: Nama Dokter | C9: : dr. | D9: Maulia Mardini, SpOG, MARS,
A10: Untuk Pembayaran
A12: Obat | B12: Prove D | E12: 1 | F12: pcs | G12: =VLOOKUP(B12,HARGA!$B$3:$D$137,3,FALSE)*E12 -> #N/A
A15: Total Pembayaran | G15: =SUM(G12:G14) -> #N/A
A17: Cara Pembayaran | C17: :
A18: Terbilang | C18: : | D18: =PROPER([1]!terbilang(G15))&"Rupiah" -> #VALUE!
G20: Diterima oleh:
G23: Nunung Nurjanah
A27: =A1 -> AL-QOYYUM ROYAL CLINIC
A28: Jl. Buana Indah No.61 Cihideung-Sadang-Purwakarta
A29: Telp : (0264)8464554 / 0813.1314.8633 (WA)
A30: BUKTI PEMBAYARAN
A31: NO : 49/0422
A33: Diterima dari | C33: : Ny. | G33: =TODAY() -> 46301
A34: Nama Pasien | C34: : | D34: ny. Yesi
A35: Nama Dokter | C35: : dr. Maulia Mardini, SpOG, MARS | D35: dr. maulia Mardini, SpOG, MARS,
A36: Untuk Pembayaran
A37: Jasa : | B37: Konsultasi Dokter | G37: FREE
B38: USG 2D | G38: FREE
A39: Obat : | B39: Cefixime | E39: 15 | F39: Pcs | G39: =VLOOKUP(B39,HARGA!$B$3:$D$181,3,FALSE)*E39 -> 105000
B40: Nova T IUD | E40: 1 | F40: Pcs | G40: =VLOOKUP(B40,HARGA!$B$3:$D$181,3,FALSE)*E40 -> 650000
A42: Total Pembayaran | G42: =SUM(G37:G41) -> 755000
A44: Cara Pembayaran | C44: : | D44: Cash
A45: Terbilang | C45: : | D45: Tujuh Ratus Lima
G47: Diterima oleh:
G50: Nunung Nurjanah

Sheet HARGA
A2: NO | B2: OBAT RESEP | C2: HARGA | D2: HARGA
A3: 1 | B3: Quatro | C3: =VLOOKUP(B3,'[2]harga obat'!B$5:K$71,10,FALSE) -> 5914.08 | D3: 6000
A4: =A3+1 -> 2 | B4: Isoflavit | C4: =VLOOKUP(B4,'[2]harga obat'!B$5:K$71,10,FALSE) -> 7920 | D4: 8000
A5: =A4+1 -> 3 | B5: Glutrop | C5: =VLOOKUP(B5,'[2]harga obat'!B$5:K$71,10,FALSE) -> 26136 | D5: 27000
A6: =A5+1 -> 4 | B6: Mozuku | C6: =VLOOKUP(B6,'[2]harga obat'!B$5:K$71,10,FALSE) -> 108000 | D6: 110000
A7: =A6+1 -> 5 | B7: Prolacta For Mother | C7: =VLOOKUP(B7,'[2]harga obat'!B$5:K$71,10,FALSE) -> 8791.2 | D7: 9000
A8: =A7+1 -> 6 | B8: Oxyvel | C8: =VLOOKUP(B8,'[2]harga obat'!B$5:K$71,10,FALSE) -> 7405.92 | D8: 7500
A9: =A8+1 -> 7 | B9: Nutriflam | C9: =VLOOKUP(B9,'[2]harga obat'!B$5:K$71,10,FALSE) -> 18849.6 | D9: 19000
A10: =A9+1 -> 8 | B10: Infusan NS | C10: =VLOOKUP(B10,'[2]harga obat'!B$5:K$71,10,FALSE) -> 0 | D10: 35000
A11: =A10+1 -> 9 | B11: Sporetik 200 | C11: =VLOOKUP(B11,'[2]harga obat'!B$5:K$71,10,FALSE) -> 42120 | D11: 43000
A12: =A11+1 -> 10 | B12: Trovensis | C12: =VLOOKUP(B12,'[2]harga obat'!B$5:K$71,10,FALSE) -> 19980 | D12: 20000
A13: =A12+1 -> 11 | B13: Mefinal | C13: =VLOOKUP(B13,'[2]harga obat'!B$5:K$71,10,FALSE) -> 23253.12 | D13: 4000
A14: =A13+1 -> 12 | B14: Sanmol | C14: =VLOOKUP(B14,'[2]harga obat'!B$5:K$71,10,FALSE) -> 760.32 | D14: 1000
A15: =A14+1 -> 13 | B15: Caldece | C15: =VLOOKUP(B15,'[2]harga obat'!B$5:K$71,10,FALSE) -> 47520 | D15: 48000
... A17: =A16+1 -> 15 | B17: Prove D3-1000 | C17: =VLOOKUP(B17,'[2]harga obat'!B$5:K$71,10,FALSE) -> 4867.2 | D17: 5000
A18: =A17+1 -> 16 | B18: Prove D3-5000 | C18: =VLOOKUP(B18,'[2]harga obat'!B$74:K$74,10) -> 7056 | D18: 7500
A19: =A17+1 -> 16 | B19: Plasminex | C19: =VLOOKUP(B19,'[2]harga obat'!B$5:K$71,10,FALSE) -> 4464 | D19: 5000
A20: =A19+1 -> 17 | B20: Floragyn | C20: =VLOOKUP(B20,'[2]harga obat'!B$5:K$71,10,FALSE) -> 23976 | D20: 24000
A21: =A20+1 -> 18 | B21: Microgest 200 mg | C21: =VLOOKUP(B21,'[2]harga obat'!B$5:K$71,10,FALSE) -> 36038.4 | D21: 37000
A22: =A21+1 -> 19 | B22: Sagestam | C22: =VLOOKUP(B22,'[2]harga obat'!B$5:K$71,10,FALSE) -> 23040 | D22: 26000
A23: =A22+1 -> 20 | B23: Apolar Desonide | C23: =VLOOKUP(B23,'[2]harga obat'!B$5:K$71,10,FALSE) -> 67824 | D23: 68000
A24: =A23+1 -> 21 | B24: Tremenza | C24: =VLOOKUP(B24,'[2]harga obat'!B$5:K$71,10,FALSE) -> 3600 | D24: 4000
A25: =A24+1 -> 22 | B25: Dopamet | C25: =VLOOKUP(B25,'[2]harga obat'!B$5:K$71,10,FALSE) -> 4320 | D25: 5000
A26: =A25+1 -> 23 | B26: Loratadine | C26: =VLOOKUP(B26,'[2]harga obat'!B$5:K$71,10,FALSE) -> 648 | D26: 1000
A27: =A26+1 -> 24 | B27: Rhinos | C27: =VLOOKUP(B27,'[2]harga obat'!B$5:K$71,10,FALSE) -> 9792 | D27: 13000
A28: =A27+1 -> 25 | B28: Lactamam | C28: =VLOOKUP(B28,'[2]harga obat'!B$5:K$71,10,FALSE) -> 4039.2 | D28: 5000
A29: =A28+1 -> 26 | B29: Nipvell | C29: =VLOOKUP(B29,'[2]harga obat'!B$5:K$71,10,FALSE) -> 67320 | D29: 68000
A30: =A29+1 -> 27 | B30: Eazycal | C30: =VLOOKUP(B30,'[2]harga obat'!B$5:K$71,10,FALSE) -> 8791.2 | D30: 9000
A31: =A30+1 -> 28 | B31: Nasal Aspirator | C31: =VLOOKUP(B31,'[2]harga obat'!B$5:K$71,10,FALSE) -> 42840 | D31: 43000
... A54: =A53+1 -> 51 | B54: Folamil Genio | C54: =VLOOKUP(B54,'[2]harga obat'!B$5:K$71,10,FALSE) -> 203796 | D54: 205000
A55: =A54+1 -> 52 | B55: Lidocain 20 mg | C55: =VLOOKUP(B55,'[2]harga obat'!B$79:J$110,9,FALSE) -> 2060.16 | D55: 2500
A56: =A55+1 -> 53 | B56: Fermom | C56: =VLOOKUP(B56,'[2]harga obat'!B$5:K$71,10,FALSE) -> 3170.16 | D56: 4000
A57: =A56+1 -> 54 | B57: Ondavell | C57: =VLOOKUP(B57,'[2]harga obat'!B$5:K$71,10,FALSE) -> 23096.88 | D57: 24000
A58: =A57+1 -> 55 | B58: Cefadroxil | C58: =VLOOKUP(B58,'[2]harga obat'!B$5:K$71,10,FALSE) -> 1072.8 | D58: 1500
A59: =A58+1 -> 56 | B59: Cefixime | C59: =VLOOKUP(B59,'[2]harga obat'!B$79:J$110,9,FALSE) -> 1329.75 | D59: 7000
A60: =A59+1 -> 57 | B60: Ranitidine | C60: =VLOOKUP(B60,'[2]harga obat'!B$5:K$71,10,FALSE) -> 576 | D60: 1000
A61: =A60+1 -> 58 | B61: Salgen Oint | C61: =VLOOKUP(B61,'[2]harga obat'!B$5:K$71,10,FALSE) -> 7776 | D61: 8000
A62: =A61+1 -> 59 | B62: Microlax | C62: =VLOOKUP(B62,'[2]harga obat'!B$5:K$71,10,FALSE) -> 28440 | D62: 30000
A63: =A62+1 -> 60 | B63: KingVit | C63: =VLOOKUP(B63,'[2]harga obat'!B$5:K$71,10,FALSE) -> 11741.616 | D63: 12000
A64: =A63+1 -> 61 | B64: QueenVit | C64: =VLOOKUP(B64,'[2]harga obat'!B$5:K$71,10,FALSE) -> 11741.616 | D64: 12000
...

Sheet KWITANSI FULL  (3)
A1: AL- QOYYUM ROYAL CLINIC
A2: Jl. Buana Indah No.61 Cihideung-Sadang-Purwakarta
A3: Telp : (0264)8464554 / 0813.1314.8633 (WA)
A4: BUKTI PEMBAYARAN
A5: ='KWITANSI FULL '!A6:G6 -> NO : 367/1026
A7: Diterima dari | C7: : Tn. | D7: Samijo | G7: =TODAY() -> 46301
A8: Nama Pasien | C8: : Ny. | D8: Nunung Nurhasanah
A9: Nama Dokter | C9: : dr. | D9: Maulia Mardini, SpOG, MARS,
A11: Untuk Pembayaran
A12: Jasa | B12: Konsultasi Dokter | G12: =VLOOKUP(B12,HARGA!$B$3:$D$181,3,FALSE) -> 120000
B13: USG 2D | G13: =VLOOKUP(B13,HARGA!$B$3:$D$181,3,FALSE) -> 80000
A14: Obat | B14: Visanne Dienogest 2 mg | E14: 14 | F14: pcs | G14: =VLOOKUP(B14,HARGA!$B$3:$D$181,3,FALSE)*E14 -> 434000
A16: Total Pembayaran | G16: =SUM(G12:G15) -> 634000
A18: Cara Pembayaran | C18: :
A19: Terbilang | C19: : | D19: =PROPER([1]!terbilang(G16))&"Rupiah" -> Enamratus Tigapuluh Empat Ribu Rupiah
G21: Diterima oleh:
G24: Nunung Nurjanah
A30: Jl. Buana Indah No.61 Cihideung-Sadang-Purwakarta
A31: Telp : (0264)8464554 / 0813.1314.8633 (WA)
A32: BUKTI PEMBAYARAN
A33: =A5 -> NO : 367/1026
A35: Diterima dari | C35: : Ny. | D35: Nabilah Ali Bajri | G35: =TODAY() -> 46301
A36: Nama Pasien | C36: : Ny. | D36: =D35 -> Nabilah Ali Bajri
A37: Nama Dokter | C37: : dr. | D37: Maulia Mardini, SpOG, MARS,
A38: Untuk Pembayaran
A39: Jasa | B39: Konsultasi Dokter | G39: FREE
B40: USG 2D | G40: 80000
B41: Ekstraksi IUD | G41: 450000
A42: Alat | B42: Kasa Steril | E42: 1 | F42: pcs | G42: 5000
A44: Total Pembayaran | G44: =SUM(G39:G42) -> 535000
A45: Cara Pembayaran | C45: :
A46: Terbilang | C46: : | D46: =PROPER([1]!terbilang(G44))&"Rupiah" -> Limaratus Tigapuluh Lima Ribu Rupiah
G47: Diterima oleh:
G50: Nunung Nurjanah

Sheet KWITANSI FULL  (2)
A1: AL- QOYYUM ROYAL CLINIC
A2: Jl. Buana Indah No.61 Cihideung-Sadang-Purwakarta
A3: Telp : (0264)8464554 / 0813.1314.8633 (WA)
A4: No. SIPD : 446/SIPD-1785/DPMPTSP/2022
A5: BUKTI PEMBAYARAN
A6: NO :339/0825
A8: Diterima dari | C8: : Ny. | D8: Sintia Nur Ningrum | G8: =TODAY() -> 46301
A9: Nama Pasien | C9: : Ny. | D9: Sintia Nur Ningrum
A10: Nama Dokter | C10: : dr. | D10: Maulia Mardini, SpOG, MARS,
A11: Untuk Pembayaran
A12: Jasa | B12: Konsultasi Dokter | G12: =VLOOKUP(B12,HARGA!$B$3:$D$137,3,FALSE) -> 120000
B13: USG 2D | G13: =VLOOKUP(B13,HARGA!$B$3:$D$137,3,FALSE) -> 80000
B14: Insersi IUD | G14: =VLOOKUP(B14,HARGA!$B$3:$D$137,3,FALSE) -> 450000
A15: Alat | B15: Nova T IUD | E15: 1 | F15: Pcs | G15: =VLOOKUP(B15,HARGA!$B$3:$D$137,3,FALSE)*E15 -> 650000
B16: Underpads | E16: 1 | F16: Pcs | G16: =VLOOKUP(B16,HARGA!$B$3:$D$137,3,FALSE)*E16 -> 10000
A17: Obat | B17: Cefixime | E17: 6 | F17: Pcs | G17: =VLOOKUP(B17,HARGA!$B$3:$D$137,3,FALSE)*E17 -> 42000
B18: Mefinal | E18: 10 | F18: Pcs | G18: =VLOOKUP(B18,HARGA!$B$3:$D$137,3,FALSE)*E18 -> 40000
A20: Total Pembayaran | G20: =SUM(G12:G18) -> 1392000
A22: Cara Pembayaran | C22: :
A23: Terbilang | C23: : | D23: =PROPER([1]!terbilang(G20))&"Rupiah" -> Satu Juta Tigaratus Sembilanpuluh Dua Ribu Rupiah
G25: Diterima oleh:
G28: Nunung Nurjanah
A33: =A1 -> AL- QOYYUM ROYAL CLINIC
A34: Jl. Buana Indah No.61 Cihideung-Sadang-Purwakarta
A35: Telp : (0264)8464554 / 0813.1314.8633 (WA)
A36: BUKTI PEMBAYARAN
A37: =A6 -> NO :339/0825
A39: Diterima dari | C39: : | D39: =D8 -> Sintia Nur Ningrum | G39: =TODAY() -> 46301
A40: Nama Pasien | C40: : | D40: =D39 -> Sintia Nur Ningrum
A41: Nama Dokter | C41: : dr. Maulia Mardini, SpOG, MARS | D41: dr. maulia Mardini, SpOG, MARS,
A42: Untuk Pembayaran
A43: Jasa | B43: Konsultasi Dokter | G43: 120000
B44: USG 2D | G44: 80000
B45: Pasang IUD | G45: 450000
B46: Angkat IUD | G46: 450000
A47: Obat | B47: Cefixime | E47: 10 | F47: pcs | G47: 20000
B48: Flasminex | E48: 10 | F48: pcs | G48: 45000
B49: Mefinal | E49: 10 | F49: pcs | G49: 22000
A50: Alat | B50: Nova T IUD | E50: 1 | F50: pcs | G50: 650000
B51: Underpads | E51: 1 | F51: pcs | G51: 5000
...

Sheet Kuretase
A1: AL-QOYYUM CLINIC
A2: Jl. Buana Indah No.61 Cihideung-Sadang-Purwakarta
A3: Telp : (0264)8464554 / 0813.1314.8633 (WA)
A4: BUKTI PEMBAYARAN
A5: ='KWITANSI FULL '!A6:G6 -> NO : 367/1026
A7: Diterima dari | C7: : Ny. | D7: Eti Apriyani | G7: =TODAY() -> 46301
A8: Nama Pasien | C8: : Ny. | D8: Eti Apriyani
A9: Nama Dokter | C9: : dr. | D9: Maulia Mardini, SpOG, MARS,
A10: Untuk Pembayaran
A11: Jasa | B11: Konsultasi Dokter | G11: =VLOOKUP(B11,HARGA!$B$3:$D$137,3,FALSE) -> 120000
B12: Dokter Kandungan | G12: 1500000
B13: Dokter Anestesi & Obat Anestesi | G13: 900000
B14: Tindakan Kuretasi | G14: 2100000
B15: Jasa Keperawatan | G15: 400000
B16: Tindakan Infus | G16: 25000
A17: Lab | B17: Glukosa Sewaktu | G17: 57000
B18: HBsAG | G18: 277000
B19: Hematologi Rutin | G19: 176000
A20: Obat | B20: Cefixime | E20: 10 | F20: pcs | G20: =VLOOKUP(B20,HARGA!$B$3:$D$137,3,FALSE)*E20 -> 70000
B21: Noprostol | E21: 10 | F21: pcs | G21: =VLOOKUP(B21,HARGA!$B$3:$D$137,3,FALSE)*E21 -> 170000
B22: Prove D3-5000 | E22: 30 | F22: pcs | G22: =VLOOKUP(B22,HARGA!$B$3:$D$137,3,FALSE)*E22 -> 225000
B23: Mefinal | E23: 10 | F23: pcs | G23: =VLOOKUP(B23,HARGA!$B$3:$D$137,3,FALSE)*E23 -> 40000
B24: Ceftriaxone sodium 1 G Inj | E24: 1 | F24: ampul | G24: =VLOOKUP(B24,HARGA!$B$59:$D$85,3,FALSE) -> 45000
B25: Oxytocin inj | E25: 1 | F25: ampul | G25: =VLOOKUP(B25,HARGA!$B$3:$D$137,3,FALSE)*E25 -> 10000
B26: WI 20 Ml (Aqua Pro Injection) | E26: 1 | F26: ampul | G26: =VLOOKUP(B26,HARGA!$B$3:$D$137,3,FALSE)*E26 -> 20000
A27: BHP | B27: Betadine | E27: 1 | F27: pcs | G27: =VLOOKUP(B27,HARGA!$B$3:$D$137,3,FALSE)*E27 -> 5000
B28: Kasa | E28: 4 | F28: pcs | G28: =VLOOKUP(B28,HARGA!$B$3:$D$137,3,FALSE)*E28 -> 40000
B29: Kateter | E29: 1 | F29: pcs | G29: 15000
B30: Pot Urine | E30: 1 | F30: pcs | G30: 10000
B31: Alkohol | E31: 1 | F31: pcs | G31: 5000
B32: Spuit 5cc | E32: 1 | F32: pcs | G32: 5000
B33: Spuit 1cc | E33: 1 | F33: pcs | G33: 5000
B34: Abbocath | E34: 2 | F34: pcs | G34: 7000
B35: Infus RL | E35: 1 | F35: pcs | G35: 20000
B36: Blood Set | E36: 1 | F36: pcs | G36: 115000
B37: Underpads | E37: 1 | F37: pcs | G37: =VLOOKUP(B37,HARGA!$B$3:$D$137,3,FALSE)*E37 -> 10000
A41: Total Pembayaran | G41: =SUM(G11:G37) -> 6372000
A43: Cara Pembayaran | C43: : | D43: Cash
A44: Terbilang | C44: : | D44: =PROPER([1]!terbilang(G41))&"Rupiah" -> Enam Juta Tigaratus Tujuhpuluh Dua Ribu Rupiah
G46: Diterima oleh:
...

Sheet mabok.ngidam
A1: AL-QOYYUM CLINIC
A2: Jl. Buana Indah No.61 Cihideung-Sadang-Purwakarta
A3: Telp : (0264)8464554 / 0813.1314.8633 (WA)
A4: BUKTI PEMBAYARAN
A5: ='KWITANSI FULL '!A6:G6 -> NO : 367/1026
A7: Diterima dari | C7: : Ny. | D7: Hilim Ristiani | G7: =TODAY() -> 46301
A8: Nama Pasien | C8: : Ny. | D8: Hilim Ristiani
A9: Nama Dokter | C9: : dr. | D9: Maulia Mardini, SpOG, MARS,
A10: Untuk Pembayaran
A11: Jasa | B11: Konsultasi Dokter | G11: =VLOOKUP(B11,HARGA!$B$3:$D$137,3,FALSE) -> 120000
B12: Biaya Tindakan | G12: 100000
A13: Obat | B13: Infusan NS | E13: 1 | F13: pcs | G13: =VLOOKUP(B13,HARGA!$B$3:$D$137,3,FALSE)*E13 -> 35000
B14: Infusan RL | E14: 1 | F14: pcs | G14: 35000
B15: Blood Set | E15: 1 | F15: pcs | G15: 12000
B16: Spluit 10 cc | E16: 1 | F16: pcs | G16: 5000
B17: Spluit 5 cc | E17: 2 | F17: pcs | G17: 10000
B18: Trovensis Inj | E18: 1 | F18: pcs | G18: =VLOOKUP(B18,HARGA!$B$3:$D$137,3,FALSE) -> 300000
B19: Pumpisel Inj (serbuk) | E19: 1 | F19: pcs | G19: =VLOOKUP(B19,HARGA!$B$3:$D$137,3,FALSE) -> 260000
B20: Inflo 22 Onemade | E20: 1 | F20: pcs | G20: 7000
B21: Alkohol Swab | E21: 6 | F21: pcs | G21: 5000
B22: Neurosanbe | E22: 1 | F22: pcs | G22: 10000
B23: Ondavell | E23: 3 | F23: pcs | G23: 90000
B24: Trovensis | E24: 5 | F24: pcs | G24: 90000
A26: Total Pembayaran | G26: =SUM(G11:G24) -> 1079000
A28: Cara Pembayaran | C28: : | D28: Cash
A29: Terbilang | C29: : | D29: Satu Juta Tujuh Puluh Sembilan Ribu Rupiah
G31: Diterima oleh:
G34: Nunung Nurjanah
A38: AL-QOYYUM CLINIC
A39: Jl. Buana Indah No.61 Cihideung-Sadang-Purwakarta
A40: Telp : (0264)8464554 / 8464.0858.9003 (WA)
A41: BUKTI PEMBAYARAN
A42: =A5 -> NO : 367/1026
A44: Diterima dari | C44: : | D44: =D7 -> Hilim Ristiani | G44: =TODAY() -> 46301
A45: Nama Pasien | C45: : | D45: =D44 -> Hilim Ristiani
A46: Nama Dokter | C46: : dr. Maulia Mardini, SpOG, MARS | D46: dr. maulia Mardini, SpOG, MARS,
A47: Untuk Pembayaran
A48: =A13 -> Obat | G48: =G13 -> 35000
A53: Total Pembayaran
A55: Cara Pembayaran | C55: : | D55: Cash
...

Sheet lahiran
A1: AL- QOYYUM ROYAL CLINIC
A2: Jl. Buana Indah No.61 Cihideung-Sadang-Purwakarta
A3: Telp : (0264)8464554 / 0813.1314.8633 (WA)
A4: BUKTI PEMBAYARAN
A5: NO : 560/0423
A7: Diterima dari | C7: : Drg. | D7: Aghnia Khairunnisa A | G7: =TODAY() -> 46301
A8: Nama Pasien | C8: : Drg. | D8: =D7 -> Aghnia Khairunnisa A
A9: Nama Dokter | C9: : dr. | D9: Maulia Mardini, SpOG, MARS,
A10: Untuk Pembayaran
A11: Jasa Tindakan | G11: 4250000
A12: Obat | G12: 635000
A13: Alat Kesehatan | G13: 975000
A14: Ruangan | G14: 1300000
A15: Lain-lain | G15: 340000
B17: Total | G17: =SUM(G11:G15) -> 7500000
A19: Cara Pembayaran | C19: :
A20: Terbilang | C20: : | D20: Tujuh Juta Lima Ratus Ribu Rupiah
G22: Diterima oleh:
G25: Nunung Nurjanah
A30: =A1 -> AL- QOYYUM ROYAL CLINIC
A31: Jl. Buana Indah No.61 Cihideung-Sadang-Purwakarta
A32: Telp : (0264)8464554 / 0813.1314.8633 (WA)
A33: BUKTI PEMBAYARAN
A34: NO : 560/0423
A36: Diterima dari | C36: : Drg. | D36: Risma Komala | G36: =TODAY() -> 46301
A37: Nama Pasien | C37: : Drg. | D37: =D36 -> Risma Komala
A38: Nama Dokter | C38: : dr. Maulia Mardini, SpOG, MARS | D38: dr. maulia Mardini, SpOG, MARS,
A39: Untuk Pembayaran
A40: Jasa | B40: Konsultasi Dokter | G40: 120000
B41: USG 2D | G41: 80000
B42: Pasang IUD | G42: 450000
B43: Angkat IUD | G43: 450000
A44: Obat | B44: Cefixime | E44: 10 | F44: pcs | G44: 20000
A45: Alat | B45: Nova T IUD | E45: 1 | F45: pcs | G45: 650000
B46: Underpads | E46: 1 | F46: pcs | G46: 5000
B47: Kasa Steril | E47: 1 | F47: pcs | G47: 10000
G48: =SUM(G40:G47) -> 1785000
A49: Cara Pembayaran | C49: : | D49: Cash
A50: Terbilang | C50: : | D50: Satu Juta Tujuh Ratus Delapan Puluh Lima Ribu Rupiah
G51: Diterima oleh:
...

Sheet Kuretasi (2)
A1: AL-QOYYUM CLINIC
A2: Jl. Buana Indah No.61 Cihideung-Sadang-Purwakarta
A3: Telp : (0264)8464554 / 0813.1314.8633 (WA)
A4: BUKTI PEMBAYARAN
A5: ='KWITANSI FULL '!A6:G6 -> NO : 367/1026
A7: Diterima dari | C7: : Ny. | D7: Anisa SPD | G7: 45032
A8: Nama Pasien | C8: : Ny. | D8: Anisa SPD
A9: Nama Dokter | C9: : dr. | D9: Maulia Mardini, SpOG, MARS,
A10: Untuk Pembayaran
A12: Jasa | B12: Dokter Kandungan | G12: 1500000
B13: Dokter Anestesi & Obat Anestesi | G13: 850000
B14: Tindakan Kuretasi | G14: 1730000
B15: Administrasi | G15: 50000
B16: Jasa Keperawatan | G16: 200000
B17: Tindakan Infus | G17: 30000
B18: One Day Care | G18: 500000
A19: Obat & Alkes | G19: 640000
A21: Total Pembayaran | G21: =SUM(G12:G20) -> 5500000
A23: Cara Pembayaran | C23: : | D23: Cash
A24: Terbilang | C24: : | D24: Lima Juta Lima Ratus Ribu Rupiah
G26: Diterima oleh:
G31: Nunung Nurjanah

Sheet Pasang UID
A1: AL- QOYYUM ROYAL CLINIC
A2: Jl. Buana Indah No.61 Cihideung-Sadang-Purwakarta
A3: Telp : (0264)8464554 / 0813.1314.8633 (WA)
A4: BUKTI PEMBAYARAN
A5: NO : 577/0523
A7: Diterima dari | C7: : Ny. | D7: Desi Yulinda | G7: =TODAY() -> 46301
A8: Nama Pasien | C8: : Ny. | D8: =D7 -> Desi Yulinda
A9: Nama Dokter | C9: : dr. | D9: Maulia Mardini, SpOG, MARS,
A10: Untuk Pembayaran
A11: Jasa | B11: Konsultasi Dokter | G11: =VLOOKUP(B11,HARGA!$B$3:$D$137,3,FALSE) -> 120000
B12: USG 2D | G12: =VLOOKUP(B12,HARGA!$B$3:$D$137,3,FALSE) -> 80000
B13: Insersi IUD | G13: =VLOOKUP(B13,HARGA!$B$3:$D$137,3,FALSE) -> 450000
B14: Irigasi Vagina | G14: =VLOOKUP(B14,HARGA!$B$3:$D$137,3,FALSE) -> 275000
A15: Alat | B15: Nova T IUD | E15: 1 | F15: pcs | G15: =VLOOKUP(B15,HARGA!$B$3:$D$137,3,FALSE) -> 650000
B16: kasa | G16: =VLOOKUP(B16,HARGA!$B$3:$D$137,3,FALSE) -> 10000
A18: Total Pembayaran | G18: =SUM(G11:G16) -> 1585000
A20: Cara Pembayaran | C20: :
A21: Terbilang | C21: : | D21: Satu Juta Lima Ratus Delapan Puluh Lima Ribu Rupiah
G23: Diterima oleh:
G26: Nunung Nurjanah
A31: =A1 -> AL- QOYYUM ROYAL CLINIC
A32: Jl. Buana Indah No.61 Cihideung-Sadang-Purwakarta
A33: Telp : (0264)8464554 / 0813.1314.8633 (WA)
A34: BUKTI PEMBAYARAN
A35: NO : 399/0223
A37: Diterima dari | C37: : Ny. | D37: Fitri Yulianti | G37: =TODAY() -> 46301
A38: Nama Pasien | C38: : Ny. | D38: =D37 -> Fitri Yulianti
A39: Nama Dokter | C39: : dr. Maulia Mardini, SpOG, MARS | D39: dr. maulia Mardini, SpOG, MARS,
A40: Untuk Pembayaran
A41: Jasa | B41: Konsultasi Dokter | G41: 120000
B42: USG 2D | G42: 80000
B43: Pasang IUD | G43: 450000
A44: Obat | B44: Cefixime | E44: 10 | F44: pcs | G44: 20000
A45: Alat | B45: Nova T IUD | E45: 1 | F45: pcs | G45: 650000
B46: Underpads | E46: 1 | F46: pcs | G46: 5000
B47: Kasa Steril | E47: 1 | F47: pcs | G47: 10000
A48: Potongan | B48: Konsultasi Dokter | G48: =-G41 -> -120000
G50: =SUM(G41:G48) -> 1215000
A51: Cara Pembayaran | C51: : | D51: Cash
A52: Terbilang | C52: : | D52: Satu Juta Enam Ratus Enam Puluh Lima Ribu Rupiah
...

Sheet Kuretasi (3)
A1: AL-QOYYUM CLINIC
A2: Jl. Buana Indah No.61 Cihideung-Sadang-Purwakarta
A3: Telp : (0264)8464554 / 0813.1314.8633 (WA)
A4: BUKTI PEMBAYARAN
A5: NO : 249/1022
A7: Diterima dari | C7: : Ny. | D7: Hilim Ristiani | G7: 09 Oktober 2022
A8: Nama Pasien | C8: : Ny. | D8: Hilim Ristiani
A9: Nama Dokter | C9: : dr. | D9: Maulia Mardini, SpOG, MARS,
A10: Untuk Pembayaran
A11: Jasa | B11: Konsultasi Dokter | G11: =VLOOKUP(B11,HARGA!$B$3:$D$137,3,FALSE) -> 120000
B12: USG 2D | G12: =VLOOKUP(B12,HARGA!$B$3:$D$137,3,FALSE) -> 80000
B13: Dokter Kandungan | G13: 1500000
B14: Dokter Anestesi & Obat Anestesi | G14: 750000
B15: Tindakan Kuretase | G15: 2310000
A16: Obat & Alkes | G16: 740000
A18: Total Pembayaran | G18: =SUM(G11:G16) -> 5500000
A20: Cara Pembayaran | C20: : | D20: Cash
A21: Terbilang | C21: : | D21: Lima Juta Lima Ratus Ribu Rupiah
G23: Diterima oleh:
G28: Nunung Nurjanah
